<?xml version="1.0"?>
<robot name="bot_1">
    <material name="grey">
        <color rgba='0.7 0.7 0.7 1'/>
    </material>
    <material name="green">
        <color rgba='0 0.6 0 1'/>
    </material>
    <material name="white">
        <color rgba='1 1 1 1'/>
    </material>
    <link name='base_footprint'/>
        
    
    <link name="base_link">
        <visual>
            <geometry>
                <box size="0.6 0.4 0.2"/>
            </geometry>
            <origin xyz="0 0 0.1" rpy="0 0 0"/>
            <material name='green'></material>
        </visual>
    </link>
    <link name='lidar'>
        <visual>
            <geometry>
                <cylinder radius="0.1" length="0.05"/>
            </geometry>
            <origin xyz="0 0 0" rpy="0 0 0"/>
            <material name="white"></material> 
        </visual>
    </link>
    <link name="leftwheel">
        <visual>
            <geometry>
                <cylinder radius="0.1" length="0.05"/>
            </geometry>
            <origin xyz="0.0 0.0 0.0" rpy="1.588 0.0 0.0"/>
            <material name="grey"/>

        </visual>
    </link>
    <link name="rightwheel">
        <visual>
            <geometry>
                <cylinder radius="0.1" length="0.05"/>
            </geometry>
            <origin xyz="0.0 0.0 0.0" rpy="1.588 0.0 0.0"/>
            <material name="grey"/>

        </visual>
    </link>
    <link name='casterwheel'>
        <visual>
            <geometry>
                <sphere radius='0.05'/>
            </geometry>
            <origin xyz="0.0 0.0 0.0" rpy="0.0 0.0 0.0"/>
            <material name='grey'></material>
            
        </visual>
    </link>
    <joint name="base_lidar_joint" type="fixed">
        <parent link='base_link'/>
        <child link="lidar"/>
        <origin xyz="0 0 0.225" rpy="0 0 0"/>
    </joint>
    <joint name="baseleftwheeljoint" type="continuous">
        <parent link="base_link"/>
        <child link="leftwheel"/>
        <origin xyz="-0.15 0.225 0.0" rpy="0.0 0.0 0.0"/>
        <axis xyz="0.0 1.0 0.0"/>
        

    </joint>
    <joint name="baserightwheeljoint" type="continuous">
        <parent link="base_link"/>
        <child link="rightwheel"/>
        <origin xyz="-0.15 -0.225 0.0" rpy="0.0 0.0 0.0"/>
        <axis xyz="0.0 1.0 0.0"/>
        

    </joint>
    <joint name="basecaster" type="fixed">
        <parent link='base_link'/>
        <child link='casterwheel'/>
        <origin xyz="0.2 0.0 -0.05" rpy="0.0 0.0 0.0"/>
        
    </joint>
    <joint name='base_joint' type='fixed'>
        <parent link="base_footprint"/>
        <child link="base_link"/>
        <origin xyz="0.0 0.0 0.1" rpy="0.0 0.0 0.0"/>
        
    </joint>

</robot>
